Workbook

Sheet P1
A1: prime | B1: target | C1: relation | D1: target_type | E1: correct_key | F1: thisN | G1: thisTrialN | H1: thisRepN | I1: key_resp.keys | J1: key_resp.corr | K1: key_resp.rt | L1: key_resp.duration | M1: trials.thisRepN | N1: trials.thisTrialN | O1: trials.thisN | P1: trials.thisIndex | Q1: thisRow.t | R1: notes | S1: trial.started | T1: instr_text.started | U1: instr_key.started | V1: trial.stopped | W1: instr_key.keys | X1: instr_key.rt | Y1: instr_key.duration | Z1: fixation.started | AA1: fixation1.started | AB1: fixation1.stopped | AC1: fixation.stopped | AD1: prime.started | AE1: prime_text.started | AF1: prime.stopped | AG1: gap.started | AH1: gap1.started | AI1: gap.stopped | AJ1: target_response.started | AK1: target_text.started | AL1: key_resp.started | AM1: target_text.stopped | AN1: target_response.stopped | AO1: trials.key_resp.keys | AP1: trials.key_resp.corr | AQ1: trials.key_resp.rt | AR1: trials.key_resp.duration | AS1: response | AT1: correct | AU1: prime_text.stopped | AV1: gap1.stopped | AW1: iti.started | AX1: text.started | AY1: text.stopped | AZ1: iti.stopped | BA1: end.started | BB1: end_text.started | BC1: end_key.started | BD1: end.stopped | BE1: end_key.keys | BF1: end_key.rt | BG1: end_key.duration | BH1: participant | BI1: session | BJ1: date | BK1: expName | BL1: expVersion | BM1: psychopyVersion | BN1: frameRate | BO1: expStart | BP1: Unnamed: 67 | BQ1: participant_file | BR1: Unnamed: 65 | BS1: Unnamed: 66 | BT1: Unnamed: 56
A2: salt | B2: peppero | C2: related | D2: nonword | E2: z | F2: 0 | G2: 0 | H2: 0 | I2: z | J2: 1 | K2: 1.198947 | L2: None | M2: 0 | N2: 0 | O2: 0 | P2: 72 | Q2: 6.625895 | AD2: 6.620208 | AE2: 6.625895 | AF2: 6.736146 | AG2: 6.73622 | AH2: 6.743245 | AI2: 6.776761 | AJ2: 6.780909 | AK2: 6.788757 | AL2: 6.788757 | AN2: 7.99479 | AO2: z | AP2: 1 | AQ2: 1.198947 | AR2: None | AS2: z | AT2: TRUE | AV2: 6.788757 | BH2: 1 | BI2: 1 | BJ2: 2025-11-17_09h53.34.131 | BK2: solo project | BM2: 2025.1.1 | BN2: 121.3555 | BO2: 2025-11-17 09h53.39.476207 +0530 | BQ2: 01_solo project_2025-11-17_09h53.34.131.csv
A3: fire | B3: blanket | C3: unrelated | D3: word | E3: m | F3: 1 | G3: 1 | H3: 0 | I3: m | J3: 1 | K3: 0.556175 | L3: None | M3: 0 | N3: 1 | O3: 1 | P3: 39 | Q3: 8.005464 | AD3: 7.995167 | AE3: 8.005464 | AF3: 8.14553 | AG3: 8.145577 | AH3: 8.151998 | AI3: 8.186675 | AJ3: 8.190973 | AK3: 8.197563 | AL3: 8.197563 | AN3: 8.761426 | AO3: m | AP3: 1 | AQ3: 0.556175 | AR3: None | AS3: m | AT3: TRUE | AV3: 8.197563 | BH3: 1 | BI3: 1 | BJ3: 2025-11-17_09h53.34.131 | BK3: solo project | BM3: 2025.1.1 | BN3: 121.3555 | BO3: 2025-11-17 09h53.39.476207 +0530 | BQ3: 01_solo project_2025-11-17_09h53.34.131.csv
A4: ball | B4: mirror | C4: unrelated | D4: word | E4: m | F4: 2 | G4: 2 | H4: 0 | I4: m | J4: 1 | K4: 0.459801 | L4: None | M4: 0 | N4: 2 | O4: 2 | P4: 48 | Q4: 8.77199 | AD4: 8.761854 | AE4: 8.77199 | AF4: 8.910041 | AG4: 8.91009 | AH4: 8.919359 | AI4: 8.953219 | AJ4: 8.957163 | AK4: 8.963913 | AL4: 8.963913 | AN4: 9.42815 | AO4: m | AP4: 1 | AQ4: 0.459801 | AR4: None | AS4: m | AT4: TRUE | AU4: 8.919359 | AV4: 8.963913 | BH4: 1 | BI4: 1 | BJ4: 2025-11-17_09h53.34.131 | BK4: solo project | BM4: 2025.1.1 | BN4: 121.3555 | BO4: 2025-11-17 09h53.39.476207 +0530 | BQ4: 01_solo project_2025-11-17_09h53.34.131.csv
A5: teacher | B5: student | C5: related | D5: word | E5: m | F5: 3 | G5: 3 | H5: 0 | I5: m | J5: 1 | K5: 0.486474 | L5: None | M5: 0 | N5: 3 | O5: 3 | P5: 4 | Q5: 9.447045 | AD5: 9.428621 | AE5: 9.447045 | AF5: 9.586916 | AG5: 9.586996 | AH5: 9.593891 | AI5: 9.636144 | AJ5: 9.640589 | AK5: 9.647249 | AL5: 9.647249 | AN5: 10.13815 | AO5: m | AP5: 1 | AQ5: 0.486474 | AR5: None | AS5: m | AT5: TRUE | BH5: 1 | BI5: 1 | BJ5: 2025-11-17_09h53.34.131 | BK5: solo project | BM5: 2025.1.1 | BN5: 121.3555 | BO5: 2025-11-17 09h53.39.476207 +0530 | BQ5: 01_solo project_2025-11-17_09h53.34.131.csv
A6: flower | B6: bottlev | C6: unrelated | D6: nonword | E6: z | F6: 4 | G6: 4 | H6: 0 | I6: z | J6: 1 | K6: 0.478482 | L6: None | M6: 0 | N6: 4 | O6: 4 | P6: 99 | Q6: 10.14869 | AD6: 10.13854 | AE6: 10.14869 | AF6: 10.28578 | AG6: 10.28584 | AH6: 10.29216 | AI6: 10.32659 | AJ6: 10.33248 | AK6: 10.33914 | AL6: 10.33914 | AN6: 10.82154 | AO6: z | AP6: 1 | AQ6: 0.478482 | AR6: None | AS6: z | AT6: TRUE | AU6: 10.29216 | AV6: 10.33914 | BH6: 1 | BI6: 1 | BJ6: 2025-11-17_09h53.34.131 | BK6: solo project | BM6: 2025.1.1 | BN6: 121.3555 | BO6: 2025-11-17 09h53.39.476207 +0530 | BQ6: 01_solo project_2025-11-17_09h53.34.131.csv
A7: road | B7: streetq | C7: related | D7: nonword | E7: z | F7: 5 | G7: 5 | H7: 0 | I7: z | J7: 1 | K7: 0.587551 | L7: None | M7: 0 | N7: 5 | O7: 5 | P7: 69 | Q7: 10.83207 | AD7: 10.82203 | AE7: 10.83207 | AF7: 10.96898 | AG7: 10.96905 | AH7: 10.9755 | AI7: 11.00975 | AJ7: 11.01389 | AK7: 11.02107 | AL7: 11.02107 | AN7: 11.61184 | AO7: z | AP7: 1 | AQ7: 0.587551 | AR7: None | AS7: z | AT7: TRUE | AU7: 10.9755 | AV7: 11.02107 | BH7: 1 | BI7: 1 | BJ7: 2025-11-17_09h53.34.131 | BK7: solo project | BM7: 2025.1.1 | BN7: 121.3555 | BO7: 2025-11-17 09h53.39.476207 +0530 | BQ7: 01_solo project_2025-11-17_09h53.34.131.csv
A8: fire | B8: heat | C8: related | D8: word | E8: m | F8: 6 | G8: 6 | H8: 0 | I8: m | J8: 1 | K8: 0.451754 | L8: None | M8: 0 | N8: 6 | O8: 6 | P8: 14 | Q8: 11.622 | AD8: 11.61232 | AE8: 11.622 | AF8: 11.75975 | AG8: 11.75983 | AH8: 11.76985 | AI8: 11.80312 | AJ8: 11.80724 | AK8: 11.8139 | AL8: 11.8139 | AN8: 12.27164 | AO8: m | AP8: 1 | AQ8: 0.451754 | AR8: None | AS8: m | AT8: TRUE | AU8: 11.76985 | AV8: 11.8139 | BH8: 1 | BI8: 1 | BJ8: 2025-11-17_09h53.34.131 | BK8: solo project | BM8: 2025.1.1 | BN8: 121.3555 | BO8: 2025-11-17 09h53.39.476207 +0530 | BQ8: 01_solo project_2025-11-17_09h53.34.131.csv
A9: car | B9: window | C9: unrelated | D9: word | E9: m | F9: 7 | G9: 7 | H9: 0 | I9: m | J9: 1 | K9: 0.528953 | L9: None | M9: 0 | N9: 7 | O9: 7 | P9: 31 | Q9: 12.28218 | AD9: 12.27219 | AE9: 12.28218 | AF9: 12.41939 | AG9: 12.41945 | AH9: 12.42575 | AI9: 12.45991 | AJ9: 12.4636 | AK9: 12.48561 | AL9: 12.48561 | AN9: 13.02145 | AO9: m | AP9: 1 | AQ9: 0.528953 | AR9: None | AS9: m | AT9: TRUE | AU9: 12.42575 | AV9: 12.48561 | BH9: 1 | BI9: 1 | BJ9: 2025-11-17_09h53.34.131 | BK9: solo project | BM9: 2025.1.1 | BN9: 121.3555 | BO9: 2025-11-17 09h53.39.476207 +0530 | BQ9: 01_solo project_2025-11-17_09h53.34.131.csv
A10: shirt | B10: cloth | C10: related | D10: word | E10: m | F10: 8 | G10: 8 | H10: 0 | I10: m | J10: 1 | K10: 0.480524 | L10: None | M10: 0 | N10: 8 | O10: 8 | P10: 16 | Q10: 13.03205 | AD10: 13.02197 | AE10: 13.03205 | AF10: 13.16982 | AG10: 13.16985 | AH10: 13.17578 | AI10: 13.20971 | AJ10: 13.21322 | AK10: 13.22028 | AL10: 13.22028 | AN10: 13.70423 | AO10: m | AP10: 1 | AQ10: 0.480524 | AR10: None | AS10: m | AT10: TRUE | AU10: 13.17578 | AV10: 13.22028 | BH10: 1 | BI10: 1 | BJ10: 2025-11-17_09h53.34.131 | BK10: solo project | BM10: 2025.1.1 | BN10: 121.3555 | BO10: 2025-11-17 09h53.39.476207 +0530 | BQ10: 01_solo project_2025-11-17_09h53.34.131.csv
A11: bread | B11: butter | C11: related | D11: word | E11: m | F11: 9 | G11: 9 | H11: 0 | I11: m | J11: 1 | K11: 0.51863 | L11: None | M11: 0 | N11: 9 | O11: 9 | P11: 3 | Q11: 13.71419 | AD11: 13.70458 | AE11: 13.71419 | AF11: 13.8535 | AG11: 13.85356 | AH11: 13.86002 | AI11: 13.90288 | AJ11: 13.90667 | AK11: 13.91329 | AL11: 13.91329 | AN11: 14.43814 | AO11: m | AP11: 1 | AQ11: 0.51863 | AR11: None | AS11: m | AT11: TRUE | AU11: 13.86002 | AV11: 13.91329 | BH11: 1 | BI11: 1 | BJ11: 2025-11-17_09h53.34.131 | BK11: solo project | BM11: 2025.1.1 | BN11: 121.3555 | BO11: 2025-11-17 09h53.39.476207 +0530 | BQ11: 01_solo project_2025-11-17_09h53.34.131.csv
A12: river | B12: chair | C12: unrelated | D12: word | E12: m | F12: 10 | G12: 10 | H12: 0 | I12: m | J12: 1 | K12: 0.493361 | L12: None | M12: 0 | N12: 10 | O12: 10 | P12: 34 | Q12: 14.44828 | AD12: 14.43859 | AE12: 14.44828 | AF12: 14.58615 | AG12: 14.58623 | AH12: 14.59282 | AI12: 14.62649 | AJ12: 14.63019 | AK12: 14.6522 | AL12: 14.6522 | AN12: 15.15465 | AO12: m | AP12: 1 | AQ12: 0.493361 | AR12: None | AS12: m | AT12: TRUE | AU12: 14.59282 | AV12: 14.6522 | BH12: 1 | BI12: 1 | BJ12: 2025-11-17_09h53.34.131 | BK12: solo project | BM12: 2025.1.1 | BN12: 121.3555 | BO12: 2025-11-17 09h53.39.476207 +0530 | BQ12: 01_solo project_2025-11-17_09h53.34.131.csv
A13: heart | B13: mountain | C13: unrelated | D13: word | E13: m | F13: 11 | G13: 11 | H13: 0 | I13: m | J13: 1 | K13: 0.494698 | L13: None | M13: 0 | N13: 11 | O13: 11 | P13: 36 | Q13: 15.16479 | AD13: 15.15503 | AE13: 15.16479 | AF13: 15.30453 | AG13: 15.30461 | AH13: 15.31202 | AI13: 15.35332 | AJ13: 15.35834 | AK13: 15.36486 | AL13: 15.36486 | AN13: 15.87174 | AO13: m | AP13: 1 | AQ13: 0.494698 | AR13: None | AS13: m | AT13: TRUE | AU13: 15.31202 | AV13: 15.36486 | BH13: 1 | BI13: 1 | BJ13: 2025-11-17_09h53.34.131 | BK13: solo project | BM13: 2025.1.1 | BN13: 121.3555 | BO13: 2025-11-17 09h53.39.476207 +0530 | BQ13: 01_solo project_2025-11-17_09h53.34.131.csv
A14: music | B14: songy | C14: related | D14: nonword | E14: z | F14: 12 | G14: 12 | H14: 0 | I14: z | J14: 1 | K14: 0.654654 | L14: None | M14: 0 | N14: 12 | O14: 12 | P14: 62 | Q14: 15.88232 | AD14: 15.87228 | AE14: 15.88232 | AF14: 16.02024 | AG14: 16.02028 | AH14: 16.02638 | AI14: 16.05946 | AJ14: 16.06355 | AK14: 16.08578 | AL14: 16.08578 | AN14: 16.74438 | AO14: z | AP14: 1 | AQ14: 0.654654 | AR14: None | AS14: z | AT14: TRUE | AU14: 16.02638 | AV14: 16.08578 | BH14: 1 | BI14: 1 | BJ14: 2025-11-17_09h53.34.131 | BK14: solo project | BM14: 2025.1.1 | BN14: 121.3555 | BO14: 2025-11-17 09h53.39.476207 +0530 | BQ14: 01_solo project_2025-11-17_09h53.34.131.csv
A15: doctor | B15: table | C15: unrelated | D15: word | E15: m | F15: 13 | G15: 13 | H15: 0 | I15: m | J15: 1 | K15: 0.612247 | L15: None | M15: 0 | N15: 13 | O15: 13 | P15: 25 | Q15: 16.75504 | AD15: 16.74477 | AE15: 16.75504 | AF15: 16.89363 | AG15: 16.89368 | AH15: 16.90289 | AI15: 16.93632 | AJ15: 16.94064 | AK15: 16.94724 | AL15: 16.94724 | AN15: 17.56161 | AO15: m | AP15: 1 | AQ15: 0.612247 | AR15: None | AS15: m | AT15: TRUE | AU15: 16.90289 | AV15: 16.94724 | BH15: 1 | BI15: 1 | BJ15: 2025-11-17_09h53.34.131 | BK15: solo project | BM15: 2025.1.1 | BN15: 121.3555 | BO15: 2025-11-17 09h53.39.476207 +0530 | BQ15: 01_solo project_2025-11-17_09h53.34.131.csv
A16: sun | B16: glass | C16: unrelated | D16: word | E16: m | F16: 14 | G16: 14 | H16: 0 | I16: m | J16: 1 | K16: 0.532746 | L16: None | M16: 0 | N16: 14 | O16: 14 | P16: 27 | Q16: 17.57233 | AD16: 17.56212 | AE16: 17.57233 | AF16: 17.71004 | AG16: 17.71009 | AH16: 17.71972 | AI16: 17.75345 | AJ16: 17.75727 | AK16: 17.76377 | AL16: 17.76377 | AN16: 18.30446 | AO16: m | AP16: 1 | AQ16: 0.532746 | AR16: None | AS16: m | AT16: TRUE | AU16: 17.71972 | AV16: 17.76377 | BH16: 1 | BI16: 1 | BJ16: 2025-11-17_09h53.34.131 | BK16: solo project | BM16: 2025.1.1 | BN16: 121.3555 | BO16: 2025-11-17 09h53.39.476207 +0530 | BQ16: 01_solo project_2025-11-17_09h53.34.131.csv
A17: ball | B17: mirrord | C17: unrelated | D17: nonword | E17: z | F17: 15 | G17: 15 | H17: 0 | I17: z | J17: 1 | K17: 0.594648 | L17: None | M17: 0 | N17: 15 | O17: 15 | P17: 98 | Q17: 18.3126 | AD17: 18.30475 | AE17: 18.3126 | AF17: 18.45297 | AG17: 18.45305 | AH17: 18.4596 | AI17: 18.50332 | AJ17: 18.50708 | AK17: 18.51382 | AL17: 18.51382 | AN17: 19.1117 | AO17: z | AP17: 1 | AQ17: 0.594648 | AR17: None | AS17: z | AT17: TRUE | AU17: 18.4596 | AV17: 18.51382 | BH17: 1 | BI17: 1 | BJ17: 2025-11-17_09h53.34.131 | BK17: solo project | BM17: 2025.1.1 | BN17: 121.3555 | BO17: 2025-11-17 09h53.39.476207 +0530 | BQ17: 01_solo project_2025-11-17_09h53.34.131.csv
A18: sun | B18: light | C18: related | D18: word | E18: m | F18: 16 | G18: 16 | H18: 0 | I18: m | J18: 1 | K18: 0.459274 | L18: None | M18: 0 | N18: 16 | O18: 16 | P18: 2 | Q18: 19.12198 | AD18: 19.11211 | AE18: 19.12198 | AF18: 19.26233 | AG18: 19.26238 | AH18: 19.26901 | AI18: 19.30302 | AJ18: 19.30749 | AK18: 19.31415 | AL18: 19.31415 | AN18: 19.77801 | AO18: m | AP18: 1 | AQ18: 0.459274 | AR18: None | AS18: m | AT18: TRUE | AV18: 19.31415 | BH18: 1 | BI18: 1 | BJ18: 2025-11-17_09h53.34.131 | BK18: solo project | BM18: 2025.1.1 | BN18: 121.3555 | BO18: 2025-11-17 09h53.39.476207 +0530 | BQ18: 01_solo project_2025-11-17_09h53.34.131.csv
A19: music | B19: plate | C19: unrelated | D19: word | E19: m | F19: 17 | G19: 17 | H19: 0 | I19: m | J19: 1 | K19: 0.499617 | L19: None | M19: 0 | N19: 17 | O19: 17 | P19: 37 | Q19: 19.78903 | AD19: 19.7784 | AE19: 19.78903 | AF19: 19.92646 | AG19: 19.92652 | AH19: 19.93643 | AI19: 19.97014 | AJ19: 19.97428 | AK19: 19.98084 | AL19: 19.98084 | AN19: 20.48848 | AO19: m | AP19: 1 | AQ19: 0.499617 | AR19: None | AS19: m | AT19: TRUE | AU19: 19.93643 | AV19: 19.98084 | BH19: 1 | BI19: 1 | BJ19: 2025-11-17_09h53.34.131 | BK19: solo project | BM19: 2025.1.1 | BN19: 121.3555 | BO19: 2025-11-17 09h53.39.476207 +0530 | BQ19: 01_solo project_2025-11-17_09h53.34.131.csv
A20: bird | B20: cupq | C20: unrelated | D20: nonword | E20: z | F20: 18 | G20: 18 | H20: 0 | I20: z | J20: 1 | K20: 0.635587 | L20: None | M20: 0 | N20: 18 | O20: 18 | P20: 85 | Q20: 20.4987 | AD20: 20.48887 | AE20: 20.4987 | AF20: 20.63579 | AG20: 20.63585 | AH20: 20.64214 | AI20: 20.67605 | AJ20: 20.67981 | AK20: 20.68682 | AL20: 20.68682 | AN20: 21.32805 | AO20: z | AP20: 1 | AQ20: 0.635587 | AR20: None | AS20: z | AT20: TRUE | AU20: 20.64214 | AV20: 20.68682 | BH20: 1 | BI20: 1 | BJ20: 2025-11-17_09h53.34.131 | BK20: solo project | BM20: 2025.1.1 | BN20: 121.3555 | BO20: 2025-11-17 09h53.39.476207 +0530 | BQ20: 01_solo project_2025-11-17_09h53.34.131.csv
A21: book | B21: pageq | C21: related | D21: nonword | E21: z | F21: 19 | G21: 19 | H21: 0 | I21: z | J21: 1 | K21: 0.51775 | L21: None | M21: 0 | N21: 19 | O21: 19 | P21: 58 | Q21: 21.33895 | AD21: 21.3285 | AE21: 21.33895 | AF21: 21.47657 | AG21: 21.47662 | AH21: 21.48638 | AI21: 21.52015 | AJ21: 21.52412 | AK21: 21.53072 | AL21: 21.53072 | AN21: 22.0547 | AO21: z | AP21: 1 | AQ21: 0.51775 | AR21: None | AS21: z | AT21: TRUE | AU21: 21.48638 | AV21: 21.53072 | BH21: 1 | BI21: 1 | BJ21: 2025-11-17_09h53.34.131 | BK21: solo project | BM21: 2025.1.1 | BN21: 121.3555 | BO21: 2025-11-17 09h53.39.476207 +0530 | BQ21: 01_solo project_2025-11-17_09h53.34.131.csv
A22: bread | B22: buttera | C22: related | D22: nonword | E22: z | F22: 20 | G22: 20 | H22: 0 | I22: z | J22: 1 | K22: 0.56399 | L22: None | M22: 0 | N22: 20 | O22: 20 | P22: 53 | Q22: 22.06189 | AD22: 22.05499 | AE22: 22.06189 | AF22: 22.19654 | AG22: 22.19658 | AH22: 22.20311 | AI22: 22.23639 | AJ22: 22.24024 | AK22: 22.2534 | AL22: 22.2534 | AN22: 22.82104 | AO22: z | AP22: 1 | AQ22: 0.56399 | AR22: None | AS22: z | AT22: TRUE | AU22: 22.20311 | AV22: 22.24612 | BH22: 1 | BI22: 1 | BJ22: 2025-11-17_09h53.34.131 | BK22: solo project | BM22: 2025.1.1 | BN22: 121.3555 | BO22: 2025-11-17 09h53.39.476207 +0530 | BQ22: 01_solo project_2025-11-17_09h53.34.131.csv
A23: shirt | B23: river | C23: unrelated | D23: word | E23: m | F23: 21 | G23: 21 | H23: 0 | I23: m | J23: 1 | K23: 0.488759 | L23: None | M23: 0 | N23: 21 | O23: 21 | P23: 41 | Q23: 22.83108 | AD23: 22.82141 | AE23: 22.83108 | AF23: 22.96951 | AG23: 22.96958 | AH23: 22.97597 | AI23: 23.00946 | AJ23: 23.01361 | AK23: 23.03555 | AL23: 23.03555 | AN23: 23.52765 | AO23: m | AP23: 1 | AQ23: 0.488759 | AR23: None | AS23: m | AT23: TRUE | AU23: 22.97597 | AV23: 23.03555 | BH23: 1 | BI23: 1 | BJ23: 2025-11-17_09h53.34.131 | BK23: solo project | BM23: 2025.1.1 | BN23: 121.3555 | BO23: 2025-11-17 09h53.39.476207 +0530 | BQ23: 01_solo project_2025-11-17_09h53.34.131.csv
A24: salt | B24: camerao | C24: unrelated | D24: nonword | E24: z | F24: 22 | G24: 22 | H24: 0 | I24: z | J24: 1 | K24: 1.017236 | L24: None | M24: 0 | N24: 22 | O24: 22 | P24: 97 | Q24: 23.53822 | AD24: 23.52806 | AE24: 23.53822 | AF24: 23.67927 | AG24: 23.67931 | AH24: 23.68555 | AI24: 23.71961 | AJ24: 23.72466 | AK24: 23.73119 | AL24: 23.73119 | AN24: 24.7549 | AO24: z | AP24: 1 | AQ24: 1.017236 | AR24: None | AS24: z | AT24: TRUE | AV24: 23.73119 | BH24: 1 | BI24: 1 | BJ24: 2025-11-17_09h53.34.131 | BK24: solo project | BM24: 2025.1.1 | BN24: 121.3555 | BO24: 2025-11-17 09h53.39.476207 +0530 | BQ24: 01_solo project_2025-11-17_09h53.34.131.csv
A25: river | B25: water | C25: related | D25: word | E25: m | F25: 23 | G25: 23 | H25: 0 | I25: m | J25: 1 | K25: 0.608345 | L25: None | M25: 0 | N25: 23 | O25: 23 | P25: 9 | Q25: 24.7654 | AD25: 24.7554 | AE25: 24.7654 | AF25: 24.90334 | AG25: 24.90342 | AH25: 24.90995 | AI25: 24.94315 | AJ25: 24.94668 | AK25: 24.96893 | AL25: 24.96893 | AN25: 25.58851 | AO25: m | AP25: 1 | AQ25: 0.608345 | AR25: None | AS25: m | AT25: TRUE | AU25: 24.90995 | AV25: 24.96893 | BH25: 1 | BI25: 1 | BJ25: 2025-11-17_09h53.34.131 | BK25: solo project | BM25: 2025.1.1 | BN25: 121.3555 | BO25: 2025-11-17 09h53.39.476207 +0530 | BQ25: 01_solo project_2025-11-17_09h53.34.131.csv
A26: sun | B26: lighta | C26: related | D26: nonword | E26: z | F26: 24 | G26: 24 | H26: 0 | I26: z | J26: 1 | K26: 0.609095 | L26: None | M26: 0 | N26: 24 | O26: 24 | P26: 52 | Q26: 25.59917 | AD26: 25.58905 | AE26: 25.59917 | AF26: 25.73597 | AG26: 25.73602 | AH26: 25.74233 | AI26: 25.77653 | AJ26: 25.78016 | AK26: 25.80222 | AL26: 25.80222 | AN26: 26.42051 | AO26: z | AP26: 1 | AQ26: 0.609095 | AR26: None | AS26: z | AT26: TRUE | AU26: 25.74233 | AV26: 25.80222 | BH26: 1 | BI26: 1 | BJ26: 2025-11-17_09h53.34.131 | BK26: solo project | BM26: 2025.1.1 | BN26: 121.3555 | BO26: 2025-11-17 09h53.39.476207 +0530 | BQ26: 01_solo project_2025-11-17_09h53.34.131.csv
A27: heart | B27: beat | C27: related | D27: word | E27: m | F27: 25 | G27: 25 | H27: 0 | I27: m | J27: 1 | K27: 0.566376 | L27: None | M27: 0 | N27: 25 | O27: 25 | P27: 11 | Q27: 26.42911 | AD27: 26.42072 | AE27: 26.42911 | AF27: 26.5699 | AG27: 26.56994 | AH27: 26.57605 | AI27: 26.60956 | AJ27: 26.61278 | AK27: 26.61992 | AL27: 26.61992 | AN27: 27.19451 | AO27: m | AP27: 1 | AQ27: 0.566376 | AR27: None | AS27: m | AT27: TRUE | AU27: 26.57605 | AV27: 26.61992 | BH27: 1 | BI27: 1 | BJ27: 2025-11-17_09h53.34.131 | BK27: solo project | BM27: 2025.1.1 | BN27: 121.3555 | BO27: 2025-11-17 09h53.39.476207 +0530 | BQ27: 01_solo project_2025-11-17_09h53.34.131.csv
A28: cat | B28: pencilu | C28: unrelated | D28: nonword | E28: z | F28: 26 | G28: 26 | H28: 0 | I28: z | J28: 1 | K28: 0.690179 | L28: None | M28: 0 | N28: 26 | O28: 26 | P28: 76 | Q28: 27.20553 | AD28: 27.19493 | AE28: 27.20553 | AF28: 27.34332 | AG28: 27.34337 | AH28: 27.35252 | AI28: 27.38642 | AJ28: 27.39048 | AK28: 27.39708 | AL28: 27.39708 | AN28: 28.09508 | AO28: z | AP28: 1 | AQ28: 0.690179 | AR28: None | AS28: z | AT28: TRUE | AU28: 27.35252 | AV28: 27.39708 | BH28: 1 | BI28: 1 | BJ28: 2025-11-17_09h53.34.131 | BK28: solo project | BM28: 2025.1.1 | BN28: 121.3555 | BO28: 2025-11-17 09h53.39.476207 +0530 | BQ28: 01_solo project_2025-11-17_09h53.34.131.csv
A29: shirt | B29: riverl | C29: unrelated | D29: nonword | E29: z | F29: 27 | G29: 27 | H29: 0 | I29: z | J29: 1 | K29: 0.675017 | L29: None | M29: 0 | N29: 27 | O29: 27 | P29: 91 | Q29: 28.10518 | AD29: 28.09548 | AE29: 28.10518 | AF29: 28.24296 | AG29: 28.24304 | AH29: 28.25265 | AI29: 28.28673 | AJ29: 28.29066 | AK29: 28.29726 | AL29: 28.29726 | AN29: 28.97687 | AO29: z | AP29: 1 | AQ29: 0.675017 | AR29: None | AS29: z | AT29: TRUE | AU29: 28.25265 | AV29: 28.29726 | BH29: 1 | BI29: 1 | BJ29: 2025-11-17_09h53.34.131 | BK29: solo project | BM29: 2025.1.1 | BN29: 121.3555 | BO29: 2025-11-17 09h53.39.476207 +0530 | BQ29: 01_solo project_2025-11-17_09h53.34.131.csv
A30: king | B30: queenm | C30: related | D30: nonword | E30: z | F30: 28 | G30: 28 | H30: 0 | I30: z | J30: 1 | K30: 0.88963 | L30: None | M30: 0 | N30: 28 | O30: 28 | P30: 63 | Q30: 28.9876 | AD30: 28.97723 | AE30: 28.9876 | AF30: 29.12753 | AG30: 29.12762 | AH30: 29.13614 | AI30: 29.16968 | AJ30: 29.17578 | AK30: 29.18226 | AL30: 29.18226 | AN30: 30.07815 | AO30: z | AP30: 1 | AQ30: 0.88963 | AR30: None | AS30: z | AT30: TRUE | AU30: 29.13614 | AV30: 29.18226 | BH30: 1 | BI30: 1 | BJ30: 2025-11-17_09h53.34.131 | BK30: solo project | BM30: 2025.1.1 | BN30: 121.3555 | BO30: 2025-11-17 09h53.39.476207 +0530 | BQ30: 01_solo project_2025-11-17_09h53.34.131.csv
A31: ball | B31: gameu | C31: related | D31: nonword | E31: z | F31: 29 | G31: 29 | H31: 0 | I31: z | J31: 1 | K31: 0.515585 | L31: None | M31: 0 | N31: 29 | O31: 29 | P31: 73 | Q31: 30.0887 | AD31: 30.07854 | AE31: 30.0887 | AF31: 30.22856 | AG31: 30.22863 | AH31: 30.25227 | AI31: 30.28654 | AJ31: 30.29092 | AK31: 30.29765 | AL31: 30.29765 | AN31: 30.82163 | AO31: z | AP31: 1 | AQ31: 0.515585 | AR31: None | AS31: z | AT31: TRUE | AU31: 30.25227 | BH31: 1 | BI31: 1 | BJ31: 2025-11-17_09h53.34.131 | BK31: solo project | BM31: 2025.1.1 | BN31: 121.3555 | BO31: 2025-11-17 09h53.39.476207 +0530 | BQ31: 01_solo project_2025-11-17_09h53.34.131.csv
A32: rain | B32: engine | C32: unrelated | D32: word | E32: m | F32: 30 | G32: 30 | H32: 0 | I32: m | J32: 1 | K32: 0.588649 | L32: None | M32: 0 | N32: 30 | O32: 30 | P32: 42 | Q32: 30.83201 | AD32: 30.82215 | AE32: 30.83201 | AF32: 30.96902 | AG32: 30.96907 | AH32: 30.97523 | AI32: 31.00977 | AJ32: 31.01332 | AK32: 31.0355 | AL32: 31.0355 | AN32: 31.62768 | AO32: m | AP32: 1 | AQ32: 0.588649 | AR32: None | AS32: m | AT32: TRUE | AU32: 30.97523 | AV32: 31.0355 | BH32: 1 | BI32: 1 | BJ32: 2025-11-17_09h53.34.131 | BK32: solo project | BM32: 2025.1.1 | BN32: 121.3555 | BO32: 2025-11-17 09h53.39.476207 +0530 | BQ32: 01_solo project_2025-11-17_09h53.34.131.csv
A33: pen | B33: shoe | C33: unrelated | D33: word | E33: m | F33: 31 | G33: 31 | H33: 0 | I33: m | J33: 1 | K33: 0.570164 | L33: None | M33: 0 | N33: 31 | O33: 31 | P33: 43 | Q33: 31.63842 | AD33: 31.62808 | AE33: 31.63842 | AF33: 31.77498 | AG33: 31.77502 | AH33: 31.78587 | AI33: 31.81961 | AJ33: 31.8234 | AK33: 31.83005 | AL33: 31.83005 | AN33: 32.40445 | AO33: m | AP33: 1 | AQ33: 0.570164 | AR33: None | AS33: m | AT33: TRUE | AU33: 31.78587 | AV33: 31.83005 | BH33: 1 | BI33: 1 | BJ33: 2025-11-17_09h53.34.131 | BK33: solo project | BM33: 2025.1.1 | BN33: 121.3555 | BO33: 2025-11-17 09h53.39.476207 +0530 | BQ33: 01_solo project_2025-11-17_09h53.34.131.csv
A34: phone | B34: callz | C34: related | D34: nonword | E34: z | F34: 32 | G34: 32 | H34: 0 | I34: z | J34: 1 | K34: 0.526832 | L34: None | M34: 0 | N34: 32 | O34: 32 | P34: 57 | Q34: 32.41286 | AD34: 32.40474 | AE34: 32.41286 | AF34: 32.55282 | AG34: 32.55285 | AH34: 32.55919 | AI34: 32.59266 | AJ34: 32.59621 | AK34: 32.60334 | AL34: 32.60334 | AN34: 33.13867 | AO34: z | AP34: 1 | AQ34: 0.526832 | AR34: None | AS34: z | AT34: TRUE | AU34: 32.55919 | AV34: 32.60334 | BH34: 1 | BI34: 1 | BJ34: 2025-11-17_09h53.34.131 | BK34: solo project | BM34: 2025.1.1 | BN34: 121.3555 | BO34: 2025-11-17 09h53.39.476207 +0530 | BQ34: 01_solo project_2025-11-17_09h53.34.131.csv
A35: river | B35: waterr | C35: related | D35: nonword | E35: z | F35: 33 | G35: 33 | H35: 0 | I35: z | J35: 1 | K35: 0.73439 | L35: None | M35: 0 | N35: 33 | O35: 33 | P35: 59 | Q35: 33.149 | AD35: 33.13918 | AE35: 33.149 | AF35: 33.28638 | AG35: 33.28645 | AH35: 33.29303 | AI35: 33.32605 | AJ35: 33.32958 | AK35: 33.33669 | AL35: 33.33669 | AN35: 34.07785 | AO35: z | AP35: 1 | AQ35: 0.73439 | AR35: None | AS35: z | AT35: TRUE | AU35: 33.29303 | AV35: 33.33669 | BH35: 1 | BI35: 1 | BJ35: 2025-11-17_09h53.34.131 | BK35: solo project | BM35: 2025.1.1 | BN35: 121.3555 | BO35: 2025-11-17 09h53.39.476207 +0530 | BQ35: 01_solo project_2025-11-17_09h53.34.131.csv
A36: salt | B36: pepper | C36: related | D36: word | E36: m | F36: 34 | G36: 34 | H36: 0 | I36: m | J36: 1 | K36: 0.454592 | L36: None | M36: 0 | N36: 34 | O36: 34 | P36: 22 | Q36: 34.08877 | AD36: 34.07829 | AE36: 34.08877 | AF36: 34.2265 | AG36: 34.22655 | AH36: 34.23626 | AI36: 34.27005 | AJ36: 34.27499 | AK36: 34.28157 | AL36: 34.28157 | AN36: 34.74434 | AO36: m | AP36: 1 | AQ36: 0.454592 | AR36: None | AS36: m | AT36: TRUE | AU36: 34.23626 | AV36: 34.28157 | BH36: 1 | BI36: 1 | BJ36: 2025-11-17_09h53.34.131 | BK36: solo project | BM36: 2025.1.1 | BN36: 121.3555 | BO36: 2025-11-17 09h53.39.476207 +0530 | BQ36: 01_solo project_2025-11-17_09h53.34.131.csv
A37: bread | B37: musicq | C37: unrelated | D37: nonword | E37: z | F37: 35 | G37: 35 | H37: 0 | I37: z | J37: 1 | K37: 0.62547 | L37: None | M37: 0 | N37: 35 | O37: 35 | P37: 78 | Q37: 34.75506 | AD37: 34.74474 | AE37: 34.75506 | AF37: 34.89345 | AG37: 34.8935 | AH37: 34.90282 | AI37: 34.9364 | AJ37: 34.94059 | AK37: 34.94659 | AL37: 34.94659 | AN37: 35.57831 | AO37: z | AP37: 1 | AQ37: 0.62547 | AR37: None | AS37: z | AT37: TRUE | AU37: 34.90282 | AV37: 34.94659 | BH37: 1 | BI37: 1 | BJ37: 2025-11-17_09h53.34.131 | BK37: solo project | BM37: 2025.1.1 | BN37: 121.3555 | BO37: 2025-11-17 09h53.39.476207 +0530 | BQ37: 01_solo project_2025-11-17_09h53.34.131.csv
A38: shoe | B38: sockp | C38: related | D38: nonword | E38: z | F38: 36 | G38: 36 | H38: 0 | I38: z | J38: 1 | K38: 0.612652 | L38: None | M38: 0 | N38: 36 | O38: 36 | P38: 71 | Q38: 35.58884 | AD38: 35.5787 | AE38: 35.58884 | AF38: 35.72636 | AG38: 35.72643 | AH38: 35.73572 | AI38: 35.77026 | AJ38: 35.77446 | AK38: 35.7814 | AL38: 35.7814 | AN38: 36.40524 | AO38: z | AP38: 1 | AQ38: 0.612652 | AR38: None | AS38: z | AT38: TRUE | AU38: 35.73572 | AV38: 35.7814 | BH38: 1 | BI38: 1 | BJ38: 2025-11-17_09h53.34.131 | BK38: solo project | BM38: 2025.1.1 | BN38: 121.3555 | BO38: 2025-11-17 09h53.39.476207 +0530 | BQ38: 01_solo project_2025-11-17_09h53.34.131.csv
A39: bird | B39: wingl | C39: related | D39: nonword | E39: z | F39: 37 | G39: 37 | H39: 0 | I39: z | J39: 1 | K39: 0.541271 | L39: None | M39: 0 | N39: 37 | O39: 37 | P39: 60 | Q39: 36.41558 | AD39: 36.40569 | AE39: 36.41558 | AF39: 36.55489 | AG39: 36.55497 | AH39: 36.56262 | AI39: 36.60327 | AJ39: 36.6071 | AK39: 36.61376 | AL39: 36.61376 | AN39: 37.16131 | AO39: z | AP39: 1 | AQ39: 0.541271 | AR39: None | AS39: z | AT39: TRUE | AU39: 36.56262 | AV39: 36.61376 | BH39: 1 | BI39: 1 | BJ39: 2025-11-17_09h53.34.131 | BK39: solo project | BM39: 2025.1.1 | BN39: 121.3555 | BO39: 2025-11-17 09h53.39.476207 +0530 | BQ39: 01_solo project_2025-11-17_09h53.34.131.csv
A40: doctor | B40: nursep | C40: related | D40: nonword | E40: z | F40: 38 | G40: 38 | H40: 0 | I40: z | J40: 1 | K40: 0.545863 | L40: None | M40: 0 | N40: 38 | O40: 38 | P40: 50 | Q40: 37.17202 | AD40: 37.1617 | AE40: 37.17202 | AF40: 37.30993 | AG40: 37.30999 | AH40: 37.31943 | AI40: 37.35346 | AJ40: 37.35758 | AK40: 37.36422 | AL40: 37.36422 | AN40: 37.92126 | AO40: z | AP40: 1 | AQ40: 0.545863 | AR40: None | AS40: z | AT40: TRUE | AU40: 37.31943 | AV40: 37.36422 | BH40: 1 | BI40: 1 | BJ40: 2025-11-17_09h53.34.131 | BK40: solo project | BM40: 2025.1.1 | BN40: 121.3555 | BO40: 2025-11-17 09h53.39.476207 +0530 | BQ40: 01_solo project_2025-11-17_09h53.34.131.csv
...

Sheet P2
A1: prime | B1: target | C1: relation | D1: target_type | E1: correct_key | F1: thisN | G1: thisTrialN | H1: thisRepN | I1: key_resp.keys | J1: key_resp.corr | K1: key_resp.rt | L1: key_resp.duration | M1: trials.thisRepN | N1: trials.thisTrialN | O1: trials.thisN | P1: trials.thisIndex | Q1: thisRow.t | R1: notes | S1: trial.started | T1: instr_text.started | U1: instr_key.started | V1: trial.stopped | W1: instr_key.keys | X1: instr_key.rt | Y1: instr_key.duration | Z1: fixation.started | AA1: fixation1.started | AB1: fixation1.stopped | AC1: fixation.stopped | AD1: prime.started | AE1: prime_text.started | AF1: prime.stopped | AG1: gap.started | AH1: gap1.started | AI1: gap.stopped | AJ1: target_response.started | AK1: target_text.started | AL1: key_resp.started | AM1: target_text.stopped | AN1: target_response.stopped | AO1: trials.key_resp.keys | AP1: trials.key_resp.corr | AQ1: trials.key_resp.rt | AR1: trials.key_resp.duration | AS1: response | AT1: correct | AU1: prime_text.stopped | AV1: gap1.stopped | AW1: iti.started | AX1: text.started | AY1: text.stopped | AZ1: iti.stopped | BA1: end.started | BB1: end_text.started | BC1: end_key.started | BD1: end.stopped | BE1: end_key.keys | BF1: end_key.rt | BG1: end_key.duration | BH1: participant | BI1: session | BJ1: date | BK1: expName | BL1: expVersion | BM1: psychopyVersion | BN1: frameRate | BO1: expStart | BP1: Unnamed: 67 | BQ1: participant_file | BR1: Unnamed: 65 | BS1: Unnamed: 66 | BT1: Unnamed: 56
A2: heart | B2: mountain | C2: unrelated | D2: word | E2: m | F2: 0 | G2: 0 | H2: 0 | I2: m | J2: 1 | K2: 0.793288 | L2: None | M2: 0 | N2: 0 | O2: 0 | P2: 36 | Q2: 14.37319 | AD2: 14.36717 | AE2: 14.37319 | AF2: 14.49355 | AG2: 14.49362 | AH2: 14.5007 | AI2: 14.54357 | AJ2: 14.54753 | AK2: 14.55402 | AL2: 14.55402 | AN2: 15.35294 | AO2: m | AP2: 1 | AQ2: 0.793288 | AR2: None | AS2: m | AT2: TRUE | BH2: 2 | BI2: 1 | BJ2: 2025-11-17_09h58.11.264 | BK2: solo project | BM2: 2025.1.1 | BN2: 121.3335 | BO2: 2025-11-17 09h58.18.142547 +0530 | BQ2: 02_solo project_2025-11-17_09h58.11.264.csv
A3: king | B3: markerv | C3: unrelated | D3: nonword | E3: z | F3: 1 | G3: 1 | H3: 0 | I3: z | J3: 1 | K3: 1.661418 | L3: None | M3: 0 | N3: 1 | O3: 1 | P3: 88 | Q3: 15.36363 | AD3: 15.35336 | AE3: 15.36363 | AF3: 15.50173 | AG3: 15.50178 | AH3: 15.51023 | AI3: 15.54384 | AJ3: 15.54997 | AK3: 15.55976 | AL3: 15.55976 | AM3: 17.05027 | AN3: 17.22984 | AO3: z | AP3: 1 | AQ3: 1.661418 | AR3: None | AS3: z | AT3: TRUE | AU3: 15.51023 | AV3: 15.55976 | BH3: 2 | BI3: 1 | BJ3: 2025-11-17_09h58.11.264 | BK3: solo project | BM3: 2025.1.1 | BN3: 121.3335 | BO3: 2025-11-17 09h58.18.142547 +0530 | BQ3: 02_solo project_2025-11-17_09h58.11.264.csv
A4: doctor | B4: nursep | C4: related | D4: nonword | E4: z | F4: 2 | G4: 2 | H4: 0 | I4: z | J4: 1 | K4: 1.111312 | L4: None | M4: 0 | N4: 2 | O4: 2 | P4: 50 | Q4: 17.24065 | AD4: 17.23041 | AE4: 17.24065 | AF4: 17.37798 | AG4: 17.37807 | AH4: 17.38497 | AI4: 17.41772 | AJ4: 17.42191 | AK4: 17.42887 | AL4: 17.42887 | AN4: 18.54584 | AO4: z | AP4: 1 | AQ4: 1.111312 | AR4: None | AS4: z | AT4: TRUE | AU4: 17.38497 | AV4: 17.42887 | BH4: 2 | BI4: 1 | BJ4: 2025-11-17_09h58.11.264 | BK4: solo project | BM4: 2025.1.1 | BN4: 121.3335 | BO4: 2025-11-17 09h58.18.142547 +0530 | BQ4: 02_solo project_2025-11-17_09h58.11.264.csv
A5: fire | B5: blanket | C5: unrelated | D5: word | E5: m | F5: 3 | G5: 3 | H5: 0 | I5: m | J5: 1 | K5: 1.099699 | L5: None | M5: 0 | N5: 3 | O5: 3 | P5: 39 | Q5: 18.56406 | AD5: 18.54636 | AE5: 18.56406 | AF5: 18.70059 | AG5: 18.70066 | AH5: 18.71048 | AI5: 18.74445 | AJ5: 18.7488 | AK5: 18.75545 | AL5: 18.75545 | AN5: 19.86234 | AO5: m | AP5: 1 | AQ5: 1.099699 | AR5: None | AS5: m | AT5: TRUE | AV5: 18.75545 | BH5: 2 | BI5: 1 | BJ5: 2025-11-17_09h58.11.264 | BK5: solo project | BM5: 2025.1.1 | BN5: 121.3335 | BO5: 2025-11-17 09h58.18.142547 +0530 | BQ5: 02_solo project_2025-11-17_09h58.11.264.csv
A6: rain | B6: engine | C6: unrelated | D6: word | E6: m | F6: 4 | G6: 4 | H6: 0 | I6: m | J6: 1 | K6: 0.892482 | L6: None | M6: 0 | N6: 4 | O6: 4 | P6: 42 | Q6: 19.87254 | AD6: 19.86278 | AE6: 19.87254 | AF6: 20.01135 | AG6: 20.01143 | AH6: 20.01801 | AI6: 20.0511 | AJ6: 20.05531 | AK6: 20.06258 | AL6: 20.06258 | AN6: 20.96266 | AO6: m | AP6: 1 | AQ6: 0.892482 | AR6: None | AS6: m | AT6: TRUE | AU6: 20.01801 | AV6: 20.06258 | BH6: 2 | BI6: 1 | BJ6: 2025-11-17_09h58.11.264 | BK6: solo project | BM6: 2025.1.1 | BN6: 121.3335 | BO6: 2025-11-17 09h58.18.142547 +0530 | BQ6: 02_solo project_2025-11-17_09h58.11.264.csv
A7: book | B7: pageq | C7: related | D7: nonword | E7: z | F7: 5 | G7: 5 | H7: 0 | I7: z | J7: 1 | K7: 1.007575 | L7: None | M7: 0 | N7: 5 | O7: 5 | P7: 58 | Q7: 20.97323 | AD7: 20.96317 | AE7: 20.97323 | AF7: 21.11088 | AG7: 21.11095 | AH7: 21.11754 | AI7: 21.1501 | AJ7: 21.15342 | AK7: 21.16053 | AL7: 21.16053 | AN7: 22.17818 | AO7: z | AP7: 1 | AQ7: 1.007575 | AR7: None | AS7: z | AT7: TRUE | AU7: 21.11754 | AV7: 21.16053 | BH7: 2 | BI7: 1 | BJ7: 2025-11-17_09h58.11.264 | BK7: solo project | BM7: 2025.1.1 | BN7: 121.3335 | BO7: 2025-11-17 09h58.18.142547 +0530 | BQ7: 02_solo project_2025-11-17_09h58.11.264.csv
A8: teacher | B8: banana | C8: unrelated | D8: word | E8: m | F8: 6 | G8: 6 | H8: 0 | I8: m | J8: 1 | K8: 0.731775 | L8: None | M8: 0 | N8: 6 | O8: 6 | P8: 29 | Q8: 22.18863 | AD8: 22.17859 | AE8: 22.18863 | AF8: 22.32776 | AG8: 22.32782 | AH8: 22.33403 | AI8: 22.36735 | AJ8: 22.37159 | AK8: 22.39327 | AL8: 22.39327 | AN8: 23.12909 | AO8: m | AP8: 1 | AQ8: 0.731775 | AR8: None | AS8: m | AT8: TRUE | AU8: 22.33403 | AV8: 22.39327 | BH8: 2 | BI8: 1 | BJ8: 2025-11-17_09h58.11.264 | BK8: solo project | BM8: 2025.1.1 | BN8: 121.3335 | BO8: 2025-11-17 09h58.18.142547 +0530 | BQ8: 02_solo project_2025-11-17_09h58.11.264.csv
A9: sun | B9: glass | C9: unrelated | D9: word | E9: m | F9: 7 | G9: 7 | H9: 0 | I9: m | J9: 1 | K9: 0.868255 | L9: None | M9: 0 | N9: 7 | O9: 7 | P9: 27 | Q9: 23.13972 | AD9: 23.12959 | AE9: 23.13972 | AF9: 23.27791 | AG9: 23.27799 | AH9: 23.2845 | AI9: 23.31763 | AJ9: 23.32184 | AK9: 23.32875 | AL9: 23.32875 | AN9: 24.20234 | AO9: m | AP9: 1 | AQ9: 0.868255 | AR9: None | AS9: m | AT9: TRUE | AU9: 23.2845 | AV9: 23.32875 | BH9: 2 | BI9: 1 | BJ9: 2025-11-17_09h58.11.264 | BK9: solo project | BM9: 2025.1.1 | BN9: 121.3335 | BO9: 2025-11-17 09h58.18.142547 +0530 | BQ9: 02_solo project_2025-11-17_09h58.11.264.csv
A10: salt | B10: pepper | C10: related | D10: word | E10: m | F10: 8 | G10: 8 | H10: 0 | I10: m | J10: 1 | K10: 0.950328 | L10: None | M10: 0 | N10: 8 | O10: 8 | P10: 22 | Q10: 24.21293 | AD10: 24.20279 | AE10: 24.21293 | AF10: 24.35083 | AG10: 24.35089 | AH10: 24.36044 | AI10: 24.39444 | AJ10: 24.39903 | AK10: 24.40566 | AL10: 24.40566 | AN10: 25.36177 | AO10: m | AP10: 1 | AQ10: 0.950328 | AR10: None | AS10: m | AT10: TRUE | AU10: 24.36044 | AV10: 24.40566 | BH10: 2 | BI10: 1 | BJ10: 2025-11-17_09h58.11.264 | BK10: solo project | BM10: 2025.1.1 | BN10: 121.3335 | BO10: 2025-11-17 09h58.18.142547 +0530 | BQ10: 02_solo project_2025-11-17_09h58.11.264.csv
A11: ball | B11: gameu | C11: related | D11: nonword | E11: z | F11: 9 | G11: 9 | H11: 0 | I11: z | J11: 1 | K11: 0.515783 | L11: None | M11: 0 | N11: 9 | O11: 9 | P11: 73 | Q11: 25.37015 | AD11: 25.36215 | AE11: 25.37015 | AF11: 25.51094 | AG11: 25.51101 | AH11: 25.51757 | AI11: 25.5506 | AJ11: 25.55416 | AK11: 25.56119 | AL11: 25.56119 | AN11: 26.07937 | AO11: z | AP11: 1 | AQ11: 0.515783 | AR11: None | AS11: z | AT11: TRUE | AU11: 25.51757 | AV11: 25.56119 | BH11: 2 | BI11: 1 | BJ11: 2025-11-17_09h58.11.264 | BK11: solo project | BM11: 2025.1.1 | BN11: 121.3335 | BO11: 2025-11-17 09h58.18.142547 +0530 | BQ11: 02_solo project_2025-11-17_09h58.11.264.csv
A12: shoe | B12: sock | C12: related | D12: word | E12: m | F12: 10 | G12: 10 | H12: 0 | I12: m | J12: 1 | K12: 0.893204 | L12: None | M12: 0 | N12: 10 | O12: 10 | P12: 21 | Q12: 26.08856 | AD12: 26.07993 | AE12: 26.08856 | AF12: 26.22747 | AG12: 26.22754 | AH12: 26.23408 | AI12: 26.26717 | AJ12: 26.27056 | AK12: 26.27775 | AL12: 26.27775 | AN12: 27.17934 | AO12: m | AP12: 1 | AQ12: 0.893204 | AR12: None | AS12: m | AT12: TRUE | AU12: 26.23408 | AV12: 26.27775 | BH12: 2 | BI12: 1 | BJ12: 2025-11-17_09h58.11.264 | BK12: solo project | BM12: 2025.1.1 | BN12: 121.3335 | BO12: 2025-11-17 09h58.18.142547 +0530 | BQ12: 02_solo project_2025-11-17_09h58.11.264.csv
A13: road | B13: street | C13: related | D13: word | E13: m | F13: 11 | G13: 11 | H13: 0 | I13: m | J13: 1 | K13: 0.906264 | L13: None | M13: 0 | N13: 11 | O13: 11 | P13: 19 | Q13: 27.1871 | AD13: 27.17959 | AE13: 27.1871 | AF13: 27.32746 | AG13: 27.32752 | AH13: 27.33413 | AI13: 27.36711 | AJ13: 27.37041 | AK13: 27.37763 | AL13: 27.37763 | AN13: 28.28617 | AO13: m | AP13: 1 | AQ13: 0.906264 | AR13: None | AS13: m | AT13: TRUE | AU13: 27.33413 | AV13: 27.37763 | BH13: 2 | BI13: 1 | BJ13: 2025-11-17_09h58.11.264 | BK13: solo project | BM13: 2025.1.1 | BN13: 121.3335 | BO13: 2025-11-17 09h58.18.142547 +0530 | BQ13: 02_solo project_2025-11-17_09h58.11.264.csv
A14: sun | B14: lighta | C14: related | D14: nonword | E14: z | F14: 12 | G14: 12 | H14: 0 | I14: z | J14: 1 | K14: 0.901983 | L14: None | M14: 0 | N14: 12 | O14: 12 | P14: 52 | Q14: 28.29647 | AD14: 28.28658 | AE14: 28.29647 | AF14: 28.43391 | AG14: 28.43395 | AH14: 28.44375 | AI14: 28.4779 | AJ14: 28.48225 | AK14: 28.48896 | AL14: 28.48896 | AN14: 29.39562 | AO14: z | AP14: 1 | AQ14: 0.901983 | AR14: None | AS14: z | AT14: TRUE | AU14: 28.44375 | AV14: 28.48896 | BH14: 2 | BI14: 1 | BJ14: 2025-11-17_09h58.11.264 | BK14: solo project | BM14: 2025.1.1 | BN14: 121.3335 | BO14: 2025-11-17 09h58.18.142547 +0530 | BQ14: 02_solo project_2025-11-17_09h58.11.264.csv
A15: road | B15: candley | C15: unrelated | D15: nonword | E15: z | F15: 13 | G15: 13 | H15: 0 | I15: z | J15: 1 | K15: 1.135861 | L15: None | M15: 0 | N15: 13 | O15: 13 | P15: 94 | Q15: 29.40448 | AD15: 29.39601 | AE15: 29.40448 | AF15: 29.54406 | AG15: 29.54412 | AH15: 29.55076 | AI15: 29.58399 | AJ15: 29.58783 | AK15: 29.60999 | AL15: 29.60999 | AN15: 30.75239 | AO15: z | AP15: 1 | AQ15: 1.135861 | AR15: None | AS15: z | AT15: TRUE | AU15: 29.55076 | AV15: 29.60999 | BH15: 2 | BI15: 1 | BJ15: 2025-11-17_09h58.11.264 | BK15: solo project | BM15: 2025.1.1 | BN15: 121.3335 | BO15: 2025-11-17 09h58.18.142547 +0530 | BQ15: 02_solo project_2025-11-17_09h58.11.264.csv
A16: flower | B16: bottle | C16: unrelated | D16: word | E16: m | F16: 14 | G16: 14 | H16: 0 | I16: m | J16: 1 | K16: 1.001138 | L16: None | M16: 0 | N16: 14 | O16: 14 | P16: 49 | Q16: 30.76328 | AD16: 30.75289 | AE16: 30.76328 | AF16: 30.90066 | AG16: 30.90071 | AH16: 30.91075 | AI16: 30.94405 | AJ16: 30.94816 | AK16: 30.95478 | AL16: 30.95478 | AN16: 31.96247 | AO16: m | AP16: 1 | AQ16: 1.001138 | AR16: None | AS16: m | AT16: TRUE | AU16: 30.91075 | AV16: 30.95478 | BH16: 2 | BI16: 1 | BJ16: 2025-11-17_09h58.11.264 | BK16: solo project | BM16: 2025.1.1 | BN16: 121.3335 | BO16: 2025-11-17 09h58.18.142547 +0530 | BQ16: 02_solo project_2025-11-17_09h58.11.264.csv
A17: tree | B17: speaker | C17: unrelated | D17: word | E17: m | F17: 15 | G17: 15 | H17: 0 | I17: m | J17: 1 | K17: 0.851214 | L17: None | M17: 0 | N17: 15 | O17: 15 | P17: 45 | Q17: 31.97306 | AD17: 31.96298 | AE17: 31.97306 | AF17: 32.11052 | AG17: 32.1106 | AH17: 32.11717 | AI17: 32.15081 | AJ17: 32.15447 | AK17: 32.17657 | AL17: 32.17657 | AN17: 33.03634 | AO17: m | AP17: 1 | AQ17: 0.851214 | AR17: None | AS17: m | AT17: TRUE | AU17: 32.11717 | AV17: 32.17657 | BH17: 2 | BI17: 1 | BJ17: 2025-11-17_09h58.11.264 | BK17: solo project | BM17: 2025.1.1 | BN17: 121.3335 | BO17: 2025-11-17 09h58.18.142547 +0530 | BQ17: 02_solo project_2025-11-17_09h58.11.264.csv
... A29: doctor | B29: tabler | C29: unrelated | D29: nonword | E29: z | F29: 27 | G29: 27 | H29: 0 | I29: z | J29: 1 | K29: 0.640594 | L29: None | M29: 0 | N29: 27 | O29: 27 | P29: 75 | Q29: 43.70646 | AD29: 43.69659 | AE29: 43.70646 | AF29: 43.84373 | AG29: 43.8438 | AH29: 43.85033 | AI29: 43.88393 | AJ29: 43.8877 | AK29: 43.90992 | AL29: 43.90992 | AN29: 44.55266 | AO29: z | AP29: 1 | AQ29: 0.640594 | AR29: None | AS29: z | AT29: TRUE | AU29: 43.85033 | AV29: 43.90992 | BH29: 2 | BI29: 1 | BJ29: 2025-11-17_09h58.11.264 | BK29: solo project | BM29: 2025.1.1 | BN29: 121.3335 | BO29: 2025-11-17 09h58.18.142547 +0530 | BQ29: 02_solo project_2025-11-17_09h58.11.264.csv
A30: pen | B30: shoe | C30: unrelated | D30: word | E30: m | F30: 28 | G30: 28 | H30: 0 | I30: m | J30: 1 | K30: 0.77398 | L30: None | M30: 0 | N30: 28 | O30: 28 | P30: 43 | Q30: 44.56313 | AD30: 44.55317 | AE30: 44.56313 | AF30: 44.70356 | AG30: 44.70361 | AH30: 44.71023 | AI30: 44.74414 | AJ30: 44.74787 | AK30: 44.75462 | AL30: 44.75462 | AN30: 45.53591 | AO30: m | AP30: 1 | AQ30: 0.77398 | AR30: None | AS30: m | AT30: TRUE | AV30: 44.75462 | BH30: 2 | BI30: 1 | BJ30: 2025-11-17_09h58.11.264 | BK30: solo project | BM30: 2025.1.1 | BN30: 121.3335 | BO30: 2025-11-17 09h58.18.142547 +0530 | BQ30: 02_solo project_2025-11-17_09h58.11.264.csv
A31: flower | B31: petaln | C31: related | D31: nonword | E31: z | F31: 29 | G31: 29 | H31: 0 | I31: z | J31: 1 | K31: 0.679293 | L31: None | M31: 0 | N31: 29 | O31: 29 | P31: 74 | Q31: 45.54607 | AD31: 45.53636 | AE31: 45.54607 | AF31: 45.68379 | AG31: 45.68386 | AH31: 45.69355 | AI31: 45.72743 | AJ31: 45.73141 | AK31: 45.73824 | AL31: 45.73824 | AN31: 46.42942 | AO31: z | AP31: 1 | AQ31: 0.679293 | AR31: None | AS31: z | AT31: TRUE | AU31: 45.69355 | AV31: 45.73824 | BH31: 2 | BI31: 1 | BJ31: 2025-11-17_09h58.11.264 | BK31: solo project | BM31: 2025.1.1 | BN31: 121.3335 | BO31: 2025-11-17 09h58.18.142547 +0530 | BQ31: 02_solo project_2025-11-17_09h58.11.264.csv
A32: cup | B32: teaf | C32: related | D32: nonword | E32: z | F32: 30 | G32: 30 | H32: 0 | I32: z | J32: 1 | K32: 0.8928 | L32: None | M32: 0 | N32: 30 | O32: 30 | P32: 65 | Q32: 46.43967 | AD32: 46.42981 | AE32: 46.43967 | AF32: 46.57738 | AG32: 46.57747 | AH32: 46.58403 | AI32: 46.6175 | AJ32: 46.62164 | AK32: 46.62865 | AL32: 46.62865 | AN32: 47.52944 | AO32: z | AP32: 1 | AQ32: 0.8928 | AR32: None | AS32: z | AT32: TRUE | AU32: 46.58403 | AV32: 46.62865 | BH32: 2 | BI32: 1 | BJ32: 2025-11-17_09h58.11.264 | BK32: solo project | BM32: 2025.1.1 | BN32: 121.3335 | BO32: 2025-11-17 09h58.18.142547 +0530 | BQ32: 02_solo project_2025-11-17_09h58.11.264.csv
A33: mother | B33: childo | C33: related | D33: nonword | E33: z | F33: 31 | G33: 31 | H33: 0 | I33: z | J33: 1 | K33: 0.773251 | L33: None | M33: 0 | N33: 31 | O33: 31 | P33: 55 | Q33: 47.53991 | AD33: 47.52983 | AE33: 47.53991 | AF33: 47.6771 | AG33: 47.67718 | AH33: 47.6837 | AI33: 47.71769 | AJ33: 47.72129 | AK33: 47.74316 | AL33: 47.74316 | AN33: 48.51951 | AO33: z | AP33: 1 | AQ33: 0.773251 | AR33: None | AS33: z | AT33: TRUE | AU33: 47.6837 | AV33: 47.74316 | BH33: 2 | BI33: 1 | BJ33: 2025-11-17_09h58.11.264 | BK33: solo project | BM33: 2025.1.1 | BN33: 121.3335 | BO33: 2025-11-17 09h58.18.142547 +0530 | BQ33: 02_solo project_2025-11-17_09h58.11.264.csv
A34: cup | B34: bricku | C34: unrelated | D34: nonword | E34: z | F34: 32 | G34: 32 | H34: 0 | I34: z | J34: 1 | K34: 0.6171 | L34: None | M34: 0 | N34: 32 | O34: 32 | P34: 90 | Q34: 48.52965 | AD34: 48.51999 | AE34: 48.52965 | AF34: 48.66785 | AG34: 48.66791 | AH34: 48.67659 | AI34: 48.71099 | AJ34: 48.71484 | AK34: 48.72139 | AL34: 48.72139 | AN34: 49.3462 | AO34: z | AP34: 1 | AQ34: 0.6171 | AR34: None | AS34: z | AT34: TRUE | AU34: 48.67659 | AV34: 48.72139 | BH34: 2 | BI34: 1 | BJ34: 2025-11-17_09h58.11.264 | BK34: solo project | BM34: 2025.1.1 | BN34: 121.3335 | BO34: 2025-11-17 09h58.18.142547 +0530 | BQ34: 02_solo project_2025-11-17_09h58.11.264.csv
A35: doctor | B35: table | C35: unrelated | D35: word | E35: m | F35: 33 | G35: 33 | H35: 0 | I35: m | J35: 1 | K35: 0.494973 | L35: None | M35: 0 | N35: 33 | O35: 33 | P35: 25 | Q35: 49.35644 | AD35: 49.34658 | AE35: 49.35644 | AF35: 49.49395 | AG35: 49.49402 | AH35: 49.50058 | AI35: 49.54426 | AJ35: 49.54766 | AK35: 49.55445 | AL35: 49.55445 | AN35: 50.05279 | AO35: m | AP35: 1 | AQ35: 0.494973 | AR35: None | AS35: m | AT35: TRUE | AU35: 49.50058 | AV35: 49.55445 | BH35: 2 | BI35: 1 | BJ35: 2025-11-17_09h58.11.264 | BK35: solo project | BM35: 2025.1.1 | BN35: 121.3335 | BO35: 2025-11-17 09h58.18.142547 +0530 | BQ35: 02_solo project_2025-11-17_09h58.11.264.csv
A36: car | B36: window | C36: unrelated | D36: word | E36: m | F36: 34 | G36: 34 | H36: 0 | I36: m | J36: 1 | K36: 0.75767 | L36: None | M36: 0 | N36: 34 | O36: 34 | P36: 31 | Q36: 50.06289 | AD36: 50.05324 | AE36: 50.06289 | AF36: 50.19963 | AG36: 50.19967 | AH36: 50.21065 | AI36: 50.24377 | AJ36: 50.24712 | AK36: 50.25375 | AL36: 50.25375 | AN36: 51.01837 | AO36: m | AP36: 1 | AQ36: 0.75767 | AR36: None | AS36: m | AT36: TRUE | AU36: 50.21065 | AV36: 50.25375 | BH36: 2 | BI36: 1 | BJ36: 2025-11-17_09h58.11.264 | BK36: solo project | BM36: 2025.1.1 | BN36: 121.3335 | BO36: 2025-11-17 09h58.18.142547 +0530 | BQ36: 02_solo project_2025-11-17_09h58.11.264.csv
A37: book | B37: hammerr | C37: unrelated | D37: nonword | E37: z | F37: 35 | G37: 35 | H37: 0 | I37: z | J37: 1 | K37: 0.710559 | L37: None | M37: 0 | N37: 35 | O37: 35 | P37: 83 | Q37: 51.02741 | AD37: 51.01866 | AE37: 51.02741 | AF37: 51.16097 | AG37: 51.16105 | AH37: 51.16763 | AI37: 51.21048 | AJ37: 51.2142 | AK37: 51.22085 | AL37: 51.22085 | AN37: 51.93581 | AO37: z | AP37: 1 | AQ37: 0.710559 | AR37: None | AS37: z | AT37: TRUE | AU37: 51.16763 | AV37: 51.22085 | BH37: 2 | BI37: 1 | BJ37: 2025-11-17_09h58.11.264 | BK37: solo project | BM37: 2025.1.1 | BN37: 121.3335 | BO37: 2025-11-17 09h58.18.142547 +0530 | BQ37: 02_solo project_2025-11-17_09h58.11.264.csv
A38: teacher | B38: bananaz | C38: unrelated | D38: nonword | E38: z | F38: 36 | G38: 36 | H38: 0 | I38: z | J38: 1 | K38: 0.624141 | L38: None | M38: 0 | N38: 36 | O38: 36 | P38: 79 | Q38: 51.94609 | AD38: 51.9362 | AE38: 51.94609 | AF38: 52.08388 | AG38: 52.08395 | AH38: 52.09358 | AI38: 52.12755 | AJ38: 52.13258 | AK38: 52.13929 | AL38: 52.13929 | AN38: 52.76835 | AO38: z | AP38: 1 | AQ38: 0.624141 | AR38: None | AS38: z | AT38: TRUE | AU38: 52.09358 | AV38: 52.13929 | BH38: 2 | BI38: 1 | BJ38: 2025-11-17_09h58.11.264 | BK38: solo project | BM38: 2025.1.1 | BN38: 121.3335 | BO38: 2025-11-17 09h58.18.142547 +0530 | BQ38: 02_solo project_2025-11-17_09h58.11.264.csv
A39: teacher | B39: student | C39: related | D39: word | E39: m | F39: 37 | G39: 37 | H39: 0 | I39: m | J39: 1 | K39: 0.543389 | L39: None | M39: 0 | N39: 37 | O39: 37 | P39: 4 | Q39: 52.7792 | AD39: 52.76873 | AE39: 52.7792 | AF39: 52.91995 | AG39: 52.92 | AH39: 52.92661 | AI39: 52.96058 | AJ39: 52.96437 | AK39: 52.97095 | AL39: 52.97095 | AN39: 53.51944 | AO39: m | AP39: 1 | AQ39: 0.543389 | AR39: None | AS39: m | AT39: TRUE | AV39: 52.97095 | BH39: 2 | BI39: 1 | BJ39: 2025-11-17_09h58.11.264 | BK39: solo project | BM39: 2025.1.1 | BN39: 121.3335 | BO39: 2025-11-17 09h58.18.142547 +0530 | BQ39: 02_solo project_2025-11-17_09h58.11.264.csv
A40: pen | B40: shoep | C40: unrelated | D40: nonword | E40: z | F40: 39 | G40: 39 | H40: 0 | I40: z | J40: 1 | K40: 0.956612 | L40: None | M40: 0 | N40: 39 | O40: 39 | P40: 93 | Q40: 54.4691 | AD40: 54.46248 | AE40: 54.4691 | AF40: 54.61053 | AG40: 54.6106 | AH40: 54.61691 | AI40: 54.65071 | AJ40: 54.65477 | AK40: 54.66173 | AL40: 54.66173 | AN40: 55.62927 | AO40: z | AP40: 1 | AQ40: 0.956612 | AR40: None | AS40: z | AT40: TRUE | AU40: 54.61691 | AV40: 54.66173 | BH40: 2 | BI40: 1 | BJ40: 2025-11-17_09h58.11.264 | BK40: solo project | BM40: 2025.1.1 | BN40: 121.3335 | BO40: 2025-11-17 09h58.18.142547 +0530 | BQ40: 02_solo project_2025-11-17_09h58.11.264.csv
A41: mother | B41: bottle | C41: unrelated | D41: word | E41: m | F41: 40 | G41: 40 | H41: 0 | I41: m | J41: 1 | K41: 0.561254 | L41: None | M41: 0 | N41: 40 | O41: 40 | P41: 30 | Q41: 55.63967 | AD41: 55.62968 | AE41: 55.63967 | AF41: 55.77757 | AG41: 55.77765 | AH41: 55.78427 | AI41: 55.81711 | AJ41: 55.82135 | AK41: 55.84306 | AL41: 55.84306 | AN41: 56.41225 | AO41: m | AP41: 1 | AQ41: 0.561254 | AR41: None | AS41: m | AT41: TRUE | AU41: 55.78427 | AV41: 55.84306 | BH41: 2 | BI41: 1 | BJ41: 2025-11-17_09h58.11.264 | BK41: solo project | BM41: 2025.1.1 | BN41: 121.3335 | BO41: 2025-11-17 09h58.18.142547 +0530 | BQ41: 02_solo project_2025-11-17_09h58.11.264.csv
A42: phone | B42: call | C42: related | D42: word | E42: m | F42: 41 | G42: 41 | H42: 0 | I42: m | J42: 1 | K42: 0.592135 | L42: None | M42: 0 | N42: 41 | O42: 41 | P42: 7 | Q42: 56.42257 | AD42: 56.41265 | AE42: 56.42257 | AF42: 56.56052 | AG42: 56.56058 | AH42: 56.5668 | AI42: 56.60037 | AJ42: 56.60401 | AK42: 56.61113 | AL42: 56.61113 | AN42: 57.21258 | AO42: m | AP42: 1 | AQ42: 0.592135 | AR42: None | AS42: m | AT42: TRUE | AU42: 56.5668 | AV42: 56.61113 | BH42: 2 | BI42: 1 | BJ42: 2025-11-17_09h58.11.264 | BK42: solo project | BM42: 2025.1.1 | BN42: 121.3335 | BO42: 2025-11-17 09h58.18.142547 +0530 | BQ42: 02_solo project_2025-11-17_09h58.11.264.csv
A43: cup | B43: tea | C43: related | D43: word | E43: m | F43: 42 | G43: 42 | H43: 0 | I43: m | J43: 1 | K43: 0.523212 | L43: None | M43: 0 | N43: 42 | O43: 42 | P43: 15 | Q43: 57.22293 | AD43: 57.21296 | AE43: 57.22293 | AF43: 57.36082 | AG43: 57.36087 | AH43: 57.36718 | AI43: 57.40065 | AJ43: 57.40481 | AK43: 57.41807 | AL43: 57.41807 | AN43: 57.94522 | AO43: m | AP43: 1 | AQ43: 0.523212 | AR43: None | AS43: m | AT43: TRUE | AU43: 57.36718 | AV43: 57.41807 | BH43: 2 | BI43: 1 | BJ43: 2025-11-17_09h58.11.264 | BK43: solo project | BM43: 2025.1.1 | BN43: 121.3335 | BO43: 2025-11-17 09h58.18.142547 +0530 | BQ43: 02_solo project_2025-11-17_09h58.11.264.csv
A44: flower | B44: petal | C44: related | D44: word | E44: m | F44: 43 | G44: 43 | H44: 0 | I44: m | J44: 1 | K44: 0.63056 | L44: None | M44: 0 | N44: 43 | O44: 43 | P44: 24 | Q44: 57.95558 | AD44: 57.94572 | AE44: 57.95558 | AF44: 58.09406 | AG44: 58.09414 | AH44: 58.10057 | AI44: 58.13386 | AJ44: 58.13803 | AK44: 58.15973 | AL44: 58.15973 | AN44: 58.79633 | AO44: m | AP44: 1 | AQ44: 0.63056 | AR44: None | AS44: m | AT44: TRUE | AU44: 58.10057 | AV44: 58.15973 | BH44: 2 | BI44: 1 | BJ44: 2025-11-17_09h58.11.264 | BK44: solo project | BM44: 2025.1.1 | BN44: 121.3335 | BO44: 2025-11-17 09h58.18.142547 +0530 | BQ44: 02_solo project_2025-11-17_09h58.11.264.csv
A45: ball | B45: mirror | C45: unrelated | D45: word | E45: m | F45: 44 | G45: 44 | H45: 0 | I45: m | J45: 1 | K45: 0.467318 | L45: None | M45: 0 | N45: 44 | O45: 44 | P45: 48 | Q45: 58.80709 | AD45: 58.79694 | AE45: 58.80709 | AF45: 58.94368 | AG45: 58.94372 | AH45: 58.95001 | AI45: 58.98358 | AJ45: 58.98737 | AK45: 59.00992 | AL45: 59.00992 | AN45: 59.48552 | AO45: m | AP45: 1 | AQ45: 0.467318 | AR45: None | AS45: m | AT45: TRUE | AU45: 58.95001 | AV45: 59.00992 | BH45: 2 | BI45: 1 | BJ45: 2025-11-17_09h58.11.264 | BK45: solo project | BM45: 2025.1.1 | BN45: 121.3335 | BO45: 2025-11-17 09h58.18.142547 +0530 | BQ45: 02_solo project_2025-11-17_09h58.11.264.csv
A46: river | B46: chairy | C46: unrelated | D46: nonword | E46: z | F46: 45 | G46: 45 | H46: 0 | I46: z | J46: 1 | K46: 0.941286 | L46: None | M46: 0 | N46: 45 | O46: 45 | P46: 84 | Q46: 59.49642 | AD46: 59.48596 | AE46: 59.49642 | AF46: 59.63387 | AG46: 59.63393 | AH46: 59.64375 | AI46: 59.67755 | AJ46: 59.68147 | AK46: 59.68801 | AL46: 59.68801 | AN46: 60.63554 | AO46: z | AP46: 1 | AQ46: 0.941286 | AR46: None | AS46: z | AT46: TRUE | AU46: 59.64375 | AV46: 59.68801 | BH46: 2 | BI46: 1 | BJ46: 2025-11-17_09h58.11.264 | BK46: solo project | BM46: 2025.1.1 | BN46: 121.3335 | BO46: 2025-11-17 09h58.18.142547 +0530 | BQ46: 02_solo project_2025-11-17_09h58.11.264.csv
A47: heart | B47: beat | C47: related | D47: word | E47: m | F47: 46 | G47: 46 | H47: 0 | I47: m | J47: 1 | K47: 0.535406 | L47: None | M47: 0 | N47: 46 | O47: 46 | P47: 11 | Q47: 60.64626 | AD47: 60.63599 | AE47: 60.64626 | AF47: 60.78415 | AG47: 60.78421 | AH47: 60.79397 | AI47: 60.82732 | AJ47: 60.83093 | AK47: 60.83781 | AL47: 60.83781 | AN47: 61.37924 | AO47: m | AP47: 1 | AQ47: 0.535406 | AR47: None | AS47: m | AT47: TRUE | AU47: 60.79397 | AV47: 60.83781 | BH47: 2 | BI47: 1 | BJ47: 2025-11-17_09h58.11.264 | BK47: solo project | BM47: 2025.1.1 | BN47: 121.3335 | BO47: 2025-11-17 09h58.18.142547 +0530 | BQ47: 02_solo project_2025-11-17_09h58.11.264.csv
A48: king | B48: marker | C48: unrelated | D48: word | E48: m | F48: 47 | G48: 47 | H48: 0 | I48: m | J48: 1 | K48: 1.272064 | L48: None | M48: 0 | N48: 47 | O48: 47 | P48: 38 | Q48: 61.38736 | AD48: 61.37981 | AE48: 61.38736 | AF48: 61.52712 | AG48: 61.52718 | AH48: 61.53343 | AI48: 61.56737 | AJ48: 61.57087 | AK48: 61.5931 | AL48: 61.5931 | AN48: 62.86897 | AO48: m | AP48: 1 | AQ48: 1.272064 | AR48: None | AS48: m | AT48: TRUE | AU48: 61.53343 | AV48: 61.5931 | BH48: 2 | BI48: 1 | BJ48: 2025-11-17_09h58.11.264 | BK48: solo project | BM48: 2025.1.1 | BN48: 121.3335 | BO48: 2025-11-17 09h58.18.142547 +0530 | BQ48: 02_solo project_2025-11-17_09h58.11.264.csv
A49: fire | B49: blanketi | C49: unrelated | D49: nonword | E49: z | F49: 48 | G49: 48 | H49: 0 | I49: z | J49: 1 | K49: 0.776174 | L49: None | M49: 0 | N49: 48 | O49: 48 | P49: 89 | Q49: 62.87928 | AD49: 62.86949 | AE49: 62.87928 | AF49: 63.01772 | AG49: 63.01778 | AH49: 63.02678 | AI49: 63.06053 | AJ49: 63.06544 | AK49: 63.07197 | AL49: 63.07197 | AN49: 63.85277 | AO49: z | AP49: 1 | AQ49: 0.776174 | AR49: None | AS49: z | AT49: TRUE | AU49: 63.02678 | AV49: 63.07197 | BH49: 2 | BI49: 1 | BJ49: 2025-11-17_09h58.11.264 | BK49: solo project | BM49: 2025.1.1 | BN49: 121.3335 | BO49: 2025-11-17 09h58.18.142547 +0530 | BQ49: 02_solo project_2025-11-17_09h58.11.264.csv
A50: cat | B50: dogt | C50: related | D50: nonword | E50: z | F50: 49 | G50: 49 | H50: 0 | I50: z | J50: 1 | K50: 0.610221 | L50: None | M50: 0 | N50: 49 | O50: 49 | P50: 51 | Q50: 63.86337 | AD50: 63.85326 | AE50: 63.86337 | AF50: 64.0002 | AG50: 64.00026 | AH50: 64.0105 | AI50: 64.04384 | AJ50: 64.0473 | AK50: 64.05387 | AL50: 64.05387 | AN50: 64.66925 | AO50: z | AP50: 1 | AQ50: 0.610221 | AR50: None | AS50: z | AT50: TRUE | AU50: 64.0105 | AV50: 64.05387 | BH50: 2 | BI50: 1 | BJ50: 2025-11-17_09h58.11.264 | BK50: solo project | BM50: 2025.1.1 | BN50: 121.3335 | BO50: 2025-11-17 09h58.18.142547 +0530 | BQ50: 02_solo project_2025-11-17_09h58.11.264.csv
A51: tree | B51: speakert | C51: unrelated | D51: nonword | E51: z | F51: 50 | G51: 50 | H51: 0 | I51: z | J51: 1 | K51: 0.877891 | L51: None | M51: 0 | N51: 50 | O51: 50 | P51: 95 | Q51: 64.67734 | AD51: 64.66964 | AE51: 64.67734 | AF51: 64.81663 | AG51: 64.81668 | AH51: 64.82684 | AI51: 64.86086 | AJ51: 64.86459 | AK51: 64.87123 | AL51: 64.87123 | AN51: 65.75249 | AO51: z | AP51: 1 | AQ51: 0.877891 | AR51: None | AS51: z | AT51: TRUE | AU51: 64.82684 | AV51: 64.87123 | BH51: 2 | BI51: 1 | BJ51: 2025-11-17_09h58.11.264 | BK51: solo project | BM51: 2025.1.1 | BN51: 121.3335 | BO51: 2025-11-17 09h58.18.142547 +0530 | BQ51: 02_solo project_2025-11-17_09h58.11.264.csv
...

Sheet P3
A1: prime | B1: target | C1: relation | D1: target_type | E1: correct_key | F1: thisN | G1: thisTrialN | H1: thisRepN | I1: key_resp.keys | J1: key_resp.corr | K1: key_resp.rt | L1: key_resp.duration | M1: trials.thisRepN | N1: trials.thisTrialN | O1: trials.thisN | P1: trials.thisIndex | Q1: thisRow.t | R1: notes | S1: trial.started | T1: instr_text.started | U1: instr_key.started | V1: trial.stopped | W1: instr_key.keys | X1: instr_key.rt | Y1: instr_key.duration | Z1: fixation.started | AA1: fixation1.started | AB1: fixation1.stopped | AC1: fixation.stopped | AD1: prime.started | AE1: prime_text.started | AF1: prime.stopped | AG1: gap.started | AH1: gap1.started | AI1: gap.stopped | AJ1: target_response.started | AK1: target_text.started | AL1: key_resp.started | AM1: target_text.stopped | AN1: target_response.stopped | AO1: trials.key_resp.keys | AP1: trials.key_resp.corr | AQ1: trials.key_resp.rt | AR1: trials.key_resp.duration | AS1: response | AT1: correct | AU1: prime_text.stopped | AV1: gap1.stopped | AW1: iti.started | AX1: text.started | AY1: text.stopped | AZ1: iti.stopped | BA1: end.started | BB1: end_text.started | BC1: end_key.started | BD1: end.stopped | BE1: end_key.keys | BF1: end_key.rt | BG1: end_key.duration | BH1: participant | BI1: session | BJ1: date | BK1: expName | BL1: expVersion | BM1: psychopyVersion | BN1: frameRate | BO1: expStart | BP1: Unnamed: 67 | BQ1: participant_file | BR1: Unnamed: 65 | BS1: Unnamed: 66 | BT1: Unnamed: 56
A2: mother | B2: childo | C2: related | D2: nonword | E2: z | F2: 0 | G2: 0 | H2: 0 | I2: z | J2: 1 | K2: 1.479048 | L2: None | M2: 0 | N2: 0 | O2: 0 | P2: 55 | Q2: 14.35265 | AD2: 14.34662 | AE2: 14.35265 | AF2: 14.48063 | AG2: 14.48074 | AH2: 14.48884 | AI2: 14.53103 | AJ2: 14.53513 | AK2: 14.54273 | AL2: 14.54273 | AM2: 16.04332 | AN2: 16.03276 | AO2: z | AP2: 1 | AQ2: 1.479048 | AR2: None | AS2: z | AT2: TRUE | BH2: 3 | BI2: 1 | BJ2: 2025-11-17_10h06.58.143 | BK2: solo project | BM2: 2025.1.1 | BN2: 120.0969 | BO2: 2025-11-17 10h07.04.593858 +0530 | BQ2: 03_solo project_2025-11-17_10h06.58.143.csv
A3: phone | B3: forest | C3: unrelated | D3: word | E3: m | F3: 1 | G3: 1 | H3: 0 | I3: m | J3: 1 | K3: 1.026954 | L3: None | M3: 0 | N3: 1 | O3: 1 | P3: 32 | Q3: 16.04332 | AD3: 16.03319 | AE3: 16.04332 | AF3: 16.18038 | AG3: 16.18043 | AH3: 16.18685 | AI3: 16.2208 | AJ3: 16.22459 | AK3: 16.24676 | AL3: 16.24676 | AN3: 17.28278 | AO3: m | AP3: 1 | AQ3: 1.026954 | AR3: None | AS3: m | AT3: TRUE | AU3: 16.18685 | AV3: 16.24676 | BH3: 3 | BI3: 1 | BJ3: 2025-11-17_10h06.58.143 | BK3: solo project | BM3: 2025.1.1 | BN3: 120.0969 | BO3: 2025-11-17 10h07.04.593858 +0530 | BQ3: 03_solo project_2025-11-17_10h06.58.143.csv
A4: sun | B4: glassp | C4: unrelated | D4: nonword | E4: z | F4: 2 | G4: 2 | H4: 0 | I4: z | J4: 1 | K4: 1.142094 | L4: None | M4: 0 | N4: 2 | O4: 2 | P4: 77 | Q4: 17.29289 | AD4: 17.28318 | AE4: 17.29289 | AF4: 17.43227 | AG4: 17.43234 | AH4: 17.44014 | AI4: 17.48098 | AJ4: 17.48502 | AK4: 17.49162 | AL4: 17.49162 | AN4: 18.63893 | AO4: z | AP4: 1 | AQ4: 1.142094 | AR4: None | AS4: z | AT4: TRUE | AU4: 17.44014 | AV4: 17.49162 | BH4: 3 | BI4: 1 | BJ4: 2025-11-17_10h06.58.143 | BK4: solo project | BM4: 2025.1.1 | BN4: 120.0969 | BO4: 2025-11-17 10h07.04.593858 +0530 | BQ4: 03_solo project_2025-11-17_10h06.58.143.csv
A5: road | B5: candley | C5: unrelated | D5: nonword | E5: z | F5: 3 | G5: 3 | H5: 0 | I5: z | J5: 1 | K5: 1.28427 | L5: None | M5: 0 | N5: 3 | O5: 3 | P5: 94 | Q5: 18.64957 | AD5: 18.63939 | AE5: 18.64957 | AF5: 18.788 | AG5: 18.78805 | AH5: 18.79714 | AI5: 18.83099 | AJ5: 18.83573 | AK5: 18.84238 | AL5: 18.84238 | AN5: 20.13165 | AO5: z | AP5: 1 | AQ5: 1.28427 | AR5: None | AS5: z | AT5: TRUE | AU5: 18.79714 | AV5: 18.84238 | BH5: 3 | BI5: 1 | BJ5: 2025-11-17_10h06.58.143 | BK5: solo project | BM5: 2025.1.1 | BN5: 120.0969 | BO5: 2025-11-17 10h07.04.593858 +0530 | BQ5: 03_solo project_2025-11-17_10h06.58.143.csv
A6: rain | B6: cloud | C6: related | D6: word | E6: m | F6: 4 | G6: 4 | H6: 0 | I6: m | J6: 1 | K6: 0.77732 | L6: None | M6: 0 | N6: 4 | O6: 4 | P6: 17 | Q6: 20.14804 | AD6: 20.13205 | AE6: 20.14804 | AF6: 20.28253 | AG6: 20.28259 | AH6: 20.29009 | AI6: 20.33104 | AJ6: 20.33474 | AK6: 20.3413 | AL6: 20.3413 | AN6: 21.12206 | AO6: m | AP6: 1 | AQ6: 0.77732 | AR6: None | AS6: m | AT6: TRUE | AU6: 20.29009 | AV6: 20.3413 | BH6: 3 | BI6: 1 | BJ6: 2025-11-17_10h06.58.143 | BK6: solo project | BM6: 2025.1.1 | BN6: 120.0969 | BO6: 2025-11-17 10h07.04.593858 +0530 | BQ6: 03_solo project_2025-11-17_10h06.58.143.csv
A7: ball | B7: mirrord | C7: unrelated | D7: nonword | E7: z | F7: 5 | G7: 5 | H7: 0 | I7: z | J7: 1 | K7: 1.427874 | L7: None | M7: 0 | N7: 5 | O7: 5 | P7: 98 | Q7: 21.13322 | AD7: 21.12252 | AE7: 21.13322 | AF7: 21.27375 | AG7: 21.27381 | AH7: 21.28044 | AI7: 21.31433 | AJ7: 21.3181 | AK7: 21.32476 | AL7: 21.32476 | AN7: 22.75585 | AO7: z | AP7: 1 | AQ7: 1.427874 | AR7: None | AS7: z | AT7: TRUE | AV7: 21.32476 | BH7: 3 | BI7: 1 | BJ7: 2025-11-17_10h06.58.143 | BK7: solo project | BM7: 2025.1.1 | BN7: 120.0969 | BO7: 2025-11-17 10h07.04.593858 +0530 | BQ7: 03_solo project_2025-11-17_10h06.58.143.csv
A8: tree | B8: speakert | C8: unrelated | D8: nonword | E8: z | F8: 6 | G8: 6 | H8: 0 | I8: z | J8: 1 | K8: 1.345431 | L8: None | M8: 0 | N8: 6 | O8: 6 | P8: 95 | Q8: 22.76643 | AD8: 22.75625 | AE8: 22.76643 | AF8: 22.90418 | AG8: 22.90423 | AH8: 22.91396 | AI8: 22.94775 | AJ8: 22.95253 | AK8: 22.95911 | AL8: 22.95911 | AN8: 24.31441 | AO8: z | AP8: 1 | AQ8: 1.345431 | AR8: None | AS8: z | AT8: TRUE | AU8: 22.91396 | AV8: 22.95911 | BH8: 3 | BI8: 1 | BJ8: 2025-11-17_10h06.58.143 | BK8: solo project | BM8: 2025.1.1 | BN8: 120.0969 | BO8: 2025-11-17 10h07.04.593858 +0530 | BQ8: 03_solo project_2025-11-17_10h06.58.143.csv
